Workbook

Sheet All Reports - Today
A1: Strategic Bucket | B1: Report Name | C1: Deactivate | D1: Delete | E1: Report Found
A2: Service Operational Performance | B2: Area Dashboard | E2: =_xlfn.XLOOKUP(B2,'Reports - New Category'!$B$4:$B$61,'Reports - New Category'!$A$4:$A$61,"No") -> 27
A3: Service Operational Performance | B3: Service Manager Reports | E3: =_xlfn.XLOOKUP(B3,'Reports - New Category'!$B$4:$B$61,'Reports - New Category'!$A$4:$A$61,"No") -> 20
A4: Service Operational Performance | B4: TSS Stats | E4: =_xlfn.XLOOKUP(B4,'Reports - New Category'!$B$4:$B$61,'Reports - New Category'!$A$4:$A$61,"No") -> No
A5: Service Operational Performance | B5: Response Time Report | E5: =_xlfn.XLOOKUP(B5,'Reports - New Category'!$B$4:$B$61,'Reports - New Category'!$A$4:$A$61,"No") -> No
A6: Service Operational Performance | B6: Service Capacity Model | E6: =_xlfn.XLOOKUP(B6,'Reports - New Category'!$B$4:$B$61,'Reports - New Category'!$A$4:$A$61,"No") -> 3
A7: Service Operational Performance | B7: Service Business Review | E7: =_xlfn.XLOOKUP(B7,'Reports - New Category'!$B$4:$B$61,'Reports - New Category'!$A$4:$A$61,"No") -> 22
A8: Service Operational Performance | B8: Uptime | E8: =_xlfn.XLOOKUP(B8,'Reports - New Category'!$B$4:$B$61,'Reports - New Category'!$A$4:$A$61,"No") -> 24
A9: Service Operational Performance | B9: Timeliness Viewer | E9: =_xlfn.XLOOKUP(B9,'Reports - New Category'!$B$4:$B$61,'Reports - New Category'!$A$4:$A$61,"No") -> 16
A10: Service Operational Performance | B10: My Service Excellence | E10: =_xlfn.XLOOKUP(B10,'Reports - New Category'!$B$4:$B$61,'Reports - New Category'!$A$4:$A$61,"No") -> No
A11: Service Operational Performance | B11: Service Excellence | E11: =_xlfn.XLOOKUP(B11,'Reports - New Category'!$B$4:$B$61,'Reports - New Category'!$A$4:$A$61,"No") -> 31
A12: Cost of Service & Financial Analytics | B12: Cost Per Box Model | E12: =_xlfn.XLOOKUP(B12,'Reports - New Category'!$B$4:$B$61,'Reports - New Category'!$A$4:$A$61,"No") -> 29
A13: Cost of Service & Financial Analytics | B13: Country Reports | E13: =_xlfn.XLOOKUP(B13,'Reports - New Category'!$B$4:$B$61,'Reports - New Category'!$A$4:$A$61,"No") -> 6
... A15: Cost of Service & Financial Analytics | B15: Country Margin Schedule (Core + HEMA) | E15: =_xlfn.XLOOKUP(B15,'Reports - New Category'!$B$4:$B$61,'Reports - New Category'!$A$4:$A$61,"No") -> No
A16: Cost of Service & Financial Analytics | B16: Country Margin Schedule (Transfusion) | C16: Yes | E16: =_xlfn.XLOOKUP(B16,'Reports - New Category'!$B$4:$B$61,'Reports - New Category'!$A$4:$A$61,"No") -> No
A17: Cost of Service & Financial Analytics | B17: SEAS Codes | C17: Yes | E17: =_xlfn.XLOOKUP(B17,'Reports - New Category'!$B$4:$B$61,'Reports - New Category'!$A$4:$A$61,"No") -> No
A18: Cost of Service & Financial Analytics | B18: Parts Missing Costs | C18: Yes | E18: =_xlfn.XLOOKUP(B18,'Reports - New Category'!$B$4:$B$61,'Reports - New Category'!$A$4:$A$61,"No") -> No
A19: Cost of Service & Financial Analytics | B19: PM Effectiveness Report | E19: =_xlfn.XLOOKUP(B19,'Reports - New Category'!$B$4:$B$61,'Reports - New Category'!$A$4:$A$61,"No") -> No
A20: Customer Experience & Voice of Customer | B20: Customer Dashboard | E20: =_xlfn.XLOOKUP(B20,'Reports - New Category'!$B$4:$B$61,'Reports - New Category'!$A$4:$A$61,"No") -> 37
A21: Customer Experience & Voice of Customer | B21: Customer Reports | E21: =_xlfn.XLOOKUP(B21,'Reports - New Category'!$B$4:$B$61,'Reports - New Category'!$A$4:$A$61,"No") -> No
A22: Customer Experience & Voice of Customer | B22: Net Promoter Score Reports | E22: =_xlfn.XLOOKUP(B22,'Reports - New Category'!$B$4:$B$61,'Reports - New Category'!$A$4:$A$61,"No") -> No
A23: Customer Experience & Voice of Customer | B23: Loyalty Drivers Report | E23: =_xlfn.XLOOKUP(B23,'Reports - New Category'!$B$4:$B$61,'Reports - New Category'!$A$4:$A$61,"No") -> No
A24: Customer Experience & Voice of Customer | B24: Customer 360 | E24: =_xlfn.XLOOKUP(B24,'Reports - New Category'!$B$4:$B$61,'Reports - New Category'!$A$4:$A$61,"No") -> No
A25: Customer Experience & Voice of Customer | B25: Landmark Customers | E25: =_xlfn.XLOOKUP(B25,'Reports - New Category'!$B$4:$B$61,'Reports - New Category'!$A$4:$A$61,"No") -> No
A26: Customer Experience & Voice of Customer | B26: Customer Assay Usage Report | E26: =_xlfn.XLOOKUP(B26,'Reports - New Category'!$B$4:$B$61,'Reports - New Category'!$A$4:$A$61,"No") -> 14
A27: Customer Experience & Voice of Customer | B27: CRL Management Report | E27: =_xlfn.XLOOKUP(B27,'Reports - New Category'!$B$4:$B$61,'Reports - New Category'!$A$4:$A$61,"No") -> 7
A28: Asset Performance & Reliability | B28: Mean Time Between Failures (MTBF) | C28: Yes | E28: =_xlfn.XLOOKUP(B28,'Reports - New Category'!$B$4:$B$61,'Reports - New Category'!$A$4:$A$61,"No") -> No
A29: Asset Performance & Reliability | B29: FASTR | E29: =_xlfn.XLOOKUP(B29,'Reports - New Category'!$B$4:$B$61,'Reports - New Category'!$A$4:$A$61,"No") -> 18
A30: Asset Performance & Reliability | B30: FASTR2 | E30: =_xlfn.XLOOKUP(B30,'Reports - New Category'!$B$4:$B$61,'Reports - New Category'!$A$4:$A$61,"No") -> No
A31: Asset Performance & Reliability | B31: Installed Base Viewer | E31: =_xlfn.XLOOKUP(B31,'Reports - New Category'!$B$4:$B$61,'Reports - New Category'!$A$4:$A$61,"No") -> 17
A32: Asset Performance & Reliability | B32: Instrument Maintenance | E32: =_xlfn.XLOOKUP(B32,'Reports - New Category'!$B$4:$B$61,'Reports - New Category'!$A$4:$A$61,"No") -> 35
A33: Asset Performance & Reliability | B33: SIFT Viewer | E33: =_xlfn.XLOOKUP(B33,'Reports - New Category'!$B$4:$B$61,'Reports - New Category'!$A$4:$A$61,"No") -> 13
A34: Asset Performance & Reliability | B34: Active Instrument Utilization | C34: Yes | E34: =_xlfn.XLOOKUP(B34,'Reports - New Category'!$B$4:$B$61,'Reports - New Category'!$A$4:$A$61,"No") -> 30
A35: Asset Performance & Reliability | B35: IWATCH Viewer | C35: Yes | E35: =_xlfn.XLOOKUP(B35,'Reports - New Category'!$B$4:$B$61,'Reports - New Category'!$A$4:$A$61,"No") -> No
A36: Asset Performance & Reliability | B36: Integrated Products | E36: =_xlfn.XLOOKUP(B36,'Reports - New Category'!$B$4:$B$61,'Reports - New Category'!$A$4:$A$61,"No") -> No
A37: Preventive Maintenance & Service Quality | B37: PM Monitoring | E37: =_xlfn.XLOOKUP(B37,'Reports - New Category'!$B$4:$B$61,'Reports - New Category'!$A$4:$A$61,"No") -> 41
A38: Preventive Maintenance & Service Quality | B38: Labor Duration by Experience Code | E38: =_xlfn.XLOOKUP(B38,'Reports - New Category'!$B$4:$B$61,'Reports - New Category'!$A$4:$A$61,"No") -> No
A39: Preventive Maintenance & Service Quality | B39: ISO Training Report | E39: =_xlfn.XLOOKUP(B39,'Reports - New Category'!$B$4:$B$61,'Reports - New Category'!$A$4:$A$61,"No") -> No
A40: Preventive Maintenance & Service Quality | B40: Warranty Report | E40: =_xlfn.XLOOKUP(B40,'Reports - New Category'!$B$4:$B$61,'Reports - New Category'!$A$4:$A$61,"No") -> 42
A41: AbbottLink & Digital Connectivity | B41: ONeview | D41: Yes | E41: =_xlfn.XLOOKUP(B41,'Reports - New Category'!$B$4:$B$61,'Reports - New Category'!$A$4:$A$61,"No") -> No
...

Sheet Summary
A1: GSR Dashboard Report Inventory
A2: Manager review copy • Report names preserved exactly as provided • Prepared 31 Jul 2026
A4: UNIQUE GSR REPORTS | C4: POWER BI REPORTS | E4: DUPLICATE GSR ENTRIES
A5: ='Reports - New Category'!#REF! -> #REF! | C5: 10 | E5: ='Reports - New Category'!#REF! -> #REF!
A8: Manager Review Notes
A9: 1 | B9: The GSR sheet contains 58 unique report names.
A10: 2 | B10: The Power BI sheet contains 10 actual reports; the landing page and the Weekly/Daily labels are classified separately.
A11: 3 | B11: Use the Review Status dropdown to mark each item as Keep, Review, Hide, or Not Working.
A12: 4 | B12: No report name has been renamed, corrected, or removed in this workbook.
A14: Inventory Category | B14: Count
A15: Unique GSR Reports | B15: ='Reports - New Category'!#REF! -> #REF!
A16: Power BI Reports | B16: 10
A17: Duplicate GSR Entries | B17: ='Reports - New Category'!#REF! -> #REF!

Sheet Reports - New Category
A1: GSR Report Inventory
A3: S No | B3: GSR Report Name | C3: Duplicate Check | D3: Review Status | E3: Category | F3: Deactivate | G3: Delete | H3: Shown in new UI
A4: 1 | B4: Instrument Search | C4: =IF(COUNTIF($B$4:$B$61,B4)>1,"Duplicate","") | E4: Ticket Insights | H4: yes
A5: 2 | B5: Ticket Details | C5: =IF(COUNTIF($B$4:$B$61,B5)>1,"Duplicate","") | E5: Ticket Insights | H5: not there
A6: 3 | B6: Service Capacity Model | C6: =IF(COUNTIF($B$4:$B$61,B6)>1,"Duplicate","") | E6: Service Performance Metrics | H6: yes
A7: 4 | B7: Ticket Search | C7: =IF(COUNTIF($B$4:$B$61,B7)>1,"Duplicate","") | E7: Ticket Insights | H7: yes
A8: 5 | B8: SIFT Details | C8: =IF(COUNTIF($B$4:$B$61,B8)>1,"Duplicate","") | E8: Cost of Service | H8: not there
A9: 6 | B9: Country Reports | C9: =IF(COUNTIF($B$4:$B$61,B9)>1,"Duplicate","") | E9: Instrument Performance or Reliability | H9: yes
A10: 7 | B10: CRL Management Report | C10: =IF(COUNTIF($B$4:$B$61,B10)>1,"Duplicate","") | E10: Service Performance Metrics | H10: yes
A11: 8 | B11: TSB Viewer | C11: =IF(COUNTIF($B$4:$B$61,B11)>1,"Duplicate","") | E11: Instrument Performance or Reliability | H11: yes
A12: 9 | B12: Parts Viewer | C12: =IF(COUNTIF($B$4:$B$61,B12)>1,"Duplicate","") | E12: Inventory or Parts Related | H12: yes
A13: 10 | B13: AbbottLink Census Goals & Connectivity Report | C13: =IF(COUNTIF($B$4:$B$61,B13)>1,"Duplicate","") | E13: Remote Support or AbbottLink | H13: yes
A14: 11 | B14: Assay Report | C14: =IF(COUNTIF($B$4:$B$61,B14)>1,"Duplicate","") | E14: Instrument Performance or Reliability | H14: yes
A15: 12 | B15: Aging | C15: =IF(COUNTIF($B$4:$B$61,B15)>1,"Duplicate","") | E15: Instrument Performance or Reliability | H15: yes
... A32: 29 | B32: Cost Per Box Model | C32: =IF(COUNTIF($B$4:$B$61,B32)>1,"Duplicate","") | E32: Cost of Service | H32: yes
A33: 30 | B33: Active Instrument Utilization | C33: =IF(COUNTIF($B$4:$B$61,B33)>1,"Duplicate","") | E33: Customer Experience | F33: Yes
A34: 31 | B34: Service Excellence | C34: =IF(COUNTIF($B$4:$B$61,B34)>1,"Duplicate","") | E34: Service Performance Metrics | H34: yes
A35: 32 | B35: Part Usage Data | C35: =IF(COUNTIF($B$4:$B$61,B35)>1,"Duplicate","") | E35: Inventory or Parts Related | H35: yes (not exact name)
A36: 33 | B36: Country Margin Schedule | C36: =IF(COUNTIF($B$4:$B$61,B36)>1,"Duplicate","") | E36: Finance Related | H36: yes
A37: 34 | B37: Global Service PBI Home Page | C37: =IF(COUNTIF($B$4:$B$61,B37)>1,"Duplicate","") | H37: not there
A38: 35 | B38: Instrument Maintenance | C38: =IF(COUNTIF($B$4:$B$61,B38)>1,"Duplicate","") | E38: Ticket Insights | H38: yes
A39: 36 | B39: Assay Watch | C39: =IF(COUNTIF($B$4:$B$61,B39)>1,"Duplicate","") | E39: Customer Experience | H39: yes
A40: 37 | B40: Customer Dashboard | C40: =IF(COUNTIF($B$4:$B$61,B40)>1,"Duplicate","") | E40: Customer Experience | H40: yes
A41: 38 | B41: Alinity Dashboard | C41: =IF(COUNTIF($B$4:$B$61,B41)>1,"Duplicate","") | H41: yes (TOR Dasboard)
A42: 39 | B42: IHR Customer Report | C42: =IF(COUNTIF($B$4:$B$61,B42)>1,"Duplicate","") | H42: yes
A43: 40 | B43: Global Supply Chain | C43: =IF(COUNTIF($B$4:$B$61,B43)>1,"Duplicate","") | H43: yes
A44: 41 | B44: PM Monitoring | C44: =IF(COUNTIF($B$4:$B$61,B44)>1,"Duplicate","") | H44: yes
A45: 42 | B45: Warranty Report | C45: =IF(COUNTIF($B$4:$B$61,B45)>1,"Duplicate","") | H45: yes
A46: 43 | B46: Helios Telephony System Reports | C46: =IF(COUNTIF($B$4:$B$61,B46)>1,"Duplicate","") | H46: yes
A47: 44 | B47: AbbottLink Utilization Report | C47: =IF(COUNTIF($B$4:$B$61,B47)>1,"Duplicate","") | H47: yes
A48: 45 | B48: Remote Support | C48: =IF(COUNTIF($B$4:$B$61,B48)>1,"Duplicate","") | H48: yes
A49: 46 | B49: Customer Assay Usage | C49: =IF(COUNTIF($B$4:$B$61,B49)>1,"Duplicate","") | H49: yes
A50: 47 | B50: ONeView Usage Report | C50: =IF(COUNTIF($B$4:$B$61,B50)>1,"Duplicate","") | F50: Yes
A51: 48 | B51: MTBF | C51: =IF(COUNTIF($B$4:$B$61,B51)>1,"Duplicate","") | F51: Yes
A52: 49 | B52: Test of record | C52: =IF(COUNTIF($B$4:$B$61,B52)>1,"Duplicate","") | H52: yes
A53: 50 | B53: GSR Main Menu | C53: =IF(COUNTIF($B$4:$B$61,B53)>1,"Duplicate","") | H53: not there
A54: 51 | B54: ONeview Service Mgr Report | C54: =IF(COUNTIF($B$4:$B$61,B54)>1,"Duplicate","") | H54: not there
A55: 52 | B55: Customer Parts and Accessories | C55: =IF(COUNTIF($B$4:$B$61,B55)>1,"Duplicate","") | H55: yes
A56: 53 | B56: Distributor Portal | C56: =IF(COUNTIF($B$4:$B$61,B56)>1,"Duplicate","") | H56: not there
A57: 54 | B57: ELGA | C57: =IF(COUNTIF($B$4:$B$61,B57)>1,"Duplicate","") | F57: Yes
...

Sheet Power BI Reports
A1: Power BI Report Inventory | G1: Metric | H1: Value
A2: Landing page and section labels are separated from the 10 actual Power BI reports. | G2: Actual Power BI Reports | H2: 10
A4: S No | B4: Power BI Report Name | C4: Record Type | D4: Review Status | E4: Manager Notes
A5: 1 | B5: Alinity ci High Level Reliability | C5: Report
A6: 2 | B6: Alinity ci PM and TC Status | C6: Report
A7: 3 | B7: Hard Stops – Likely Causes | C7: Report
A8: 4 | B8: Transfusion IDRS Test Volume Report | C8: Report
A9: 5 | B9: a3600 Dashboard | C9: Report
A10: 6 | B10: Alinity Online Data Quality | C10: Report
A11: 7 | B11: Alinity PdM Scorecard | C11: Report
A12: 8 | B12: Alinity s Customer Health Dashboard | C12: Report
A13: 9 | B13: Operator Maintenance | C13: Report
A14: 10 | B14: Test of Record Compliance | C14: Report

Sheet Category - LoV
B1: Report Category | D1: Report Categories
B2: Intrument Service Related | D2: Ticket Related
B3: Ticket Related | D3: Remote Support or AbbottLink
B4: Remote Support | D4: Cost of Service
B5: Cost of Service | D5: Service Performance
B6: Service Metrics | D6: Area Service Info
B7: PowerBI Reports | D7: Instrument Reliability & Performance
B8: Area Service Reports | D8: Inventory and Parts Reports
B9: Instrument Specific Reports | D9: Customer Success
B10: Inventory or Parts Related | D10: Financial Metrics
B11: AbbottLink | D11: powerBI Reports
B12: Customer Related | D12: Reference Reports
D13: Secondary Reports

Sheet Utilization top 30
B1: Report Name | C1: User Count | D1: In Peter's?
B2: Global Inventory Report | C2: 2785 | D2: =_xlfn.XLOOKUP(B2,'Reports - New Category'!$B$4:$B$61,'Reports - New Category'!$A$4:$A$61,"no") -> 28
B3: Cost Per Box Model | C3: 2977 | D3: =_xlfn.XLOOKUP(B3,'Reports - New Category'!$B$4:$B$61,'Reports - New Category'!$A$4:$A$61,"no") -> 29
B4: Area Dashboard | C4: 3004 | D4: =_xlfn.XLOOKUP(B4,'Reports - New Category'!$B$4:$B$61,'Reports - New Category'!$A$4:$A$61,"no") -> 27
B5: IBP - TSB Forecasting | C5: 3983 | D5: =_xlfn.XLOOKUP(B5,'Reports - New Category'!$B$4:$B$61,'Reports - New Category'!$A$4:$A$61,"no") -> 26
B6: Instrument Health Report | C6: 4311 | D6: =_xlfn.XLOOKUP(B6,'Reports - New Category'!$B$4:$B$61,'Reports - New Category'!$A$4:$A$61,"no") -> 25
B7: Uptime | C7: 4719 | D7: =_xlfn.XLOOKUP(B7,'Reports - New Category'!$B$4:$B$61,'Reports - New Category'!$A$4:$A$61,"no") -> 24
B8: Service Business Review | C8: 4958 | D8: =_xlfn.XLOOKUP(B8,'Reports - New Category'!$B$4:$B$61,'Reports - New Category'!$A$4:$A$61,"no") -> 22
B9: Help | C9: 5387 | D9: =_xlfn.XLOOKUP(B9,'Reports - New Category'!$B$4:$B$61,'Reports - New Category'!$A$4:$A$61,"no") -> no
B10: Service Manager Reports | C10: 7742 | D10: =_xlfn.XLOOKUP(B10,'Reports - New Category'!$B$4:$B$61,'Reports - New Category'!$A$4:$A$61,"no") -> 20
B11: Service Capacity Model - Data Entry | C11: 7953 | D11: =_xlfn.XLOOKUP(B11,'Reports - New Category'!$B$4:$B$61,'Reports - New Category'!$A$4:$A$61,"no") -> 21
B12: Installation Metrics | C12: 7998 | D12: =_xlfn.XLOOKUP(B12,'Reports - New Category'!$B$4:$B$61,'Reports - New Category'!$A$4:$A$61,"no") -> 19
B13: Installed Base Viewer | C13: 8342 | D13: =_xlfn.XLOOKUP(B13,'Reports - New Category'!$B$4:$B$61,'Reports - New Category'!$A$4:$A$61,"no") -> 17
... B31: Instrument Search | C31: 121795 | D31: =_xlfn.XLOOKUP(B31,'Reports - New Category'!$B$4:$B$61,'Reports - New Category'!$A$4:$A$61,"no") -> 1

Sheet Utilization bottom 30
B1: S.no | C1: Report Name | D1: User Count
B2: 1 | C2: Instrument Search | D2: 121795
B3: 2 | C3: Ticket Details | D3: 118996
B4: 3 | C4: Service Capacity Model | D4: 101501
B5: 4 | C5: Ticket Search | D5: 92303
B6: 5 | C6: Country Reports | D6: 73639
B7: 6 | C7: SIFT Details | D7: 54351
B8: 7 | C8: CRL Management Report | D8: 28004
B9: 8 | C9: TSB Viewer | D9: 26080
B10: 9 | C10: Parts Viewer | D10: 24090
B11: 10 | C11: AbbottLink Census Goals & Connectivity Report | D11: 22335
B12: 11 | C12: Assay Report | D12: 16935
B13: 12 | C13: SIFT Viewer | D13: 14507
... B66: 65 | C66: Access Request | D66: 2
